<?xml version="1.0" encoding="UTF-8"?>
<testng-results skipped="0" failed="3" total="6" passed="3">
  <reporter-output>
  </reporter-output>
  <suite name="Default suite" duration-ms="22818" started-at="2016-05-13T08:37:19Z" finished-at="2016-05-13T08:37:42Z">
    <groups>
    </groups>
    <test name="Default test" duration-ms="22818" started-at="2016-05-13T08:37:19Z" finished-at="2016-05-13T08:37:42Z">
      <class name="com.stta.ExampleCases.Assertion">
        <test-method status="PASS" signature="loadWebPage()[pri:0, instance:com.stta.ExampleCases.Assertion@cf93bb]" name="loadWebPage" is-config="true" duration-ms="21258" started-at="2016-05-13T15:37:19Z" finished-at="2016-05-13T15:37:41Z">
          <reporter-output>
          </reporter-output>
        </test-method> <!-- loadWebPage -->
        <test-method status="PASS" signature="Assert_Method_1()[pri:0, instance:com.stta.ExampleCases.Assertion@cf93bb]" name="Assert_Method_1" duration-ms="41" started-at="2016-05-13T15:37:41Z" finished-at="2016-05-13T15:37:41Z">
          <reporter-output>
          </reporter-output>
        </test-method> <!-- Assert_Method_1 -->
        <test-method status="FAIL" signature="Assert_Method_2()[pri:0, instance:com.stta.ExampleCases.Assertion@cf93bb]" name="Assert_Method_2" duration-ms="4" started-at="2016-05-13T15:37:41Z" finished-at="2016-05-13T15:37:41Z">
          <exception class="java.lang.AssertionError">
            <message>
              <![CDATA[expected [Test1] but found [Test]]]>
            </message>
            <full-stacktrace>
              <![CDATA[java.lang.AssertionError: expected [Test1] but found [Test]
	at org.testng.Assert.fail(Assert.java:94)
	at org.testng.Assert.failNotEquals(Assert.java:496)
	at org.testng.Assert.assertEquals(Assert.java:125)
	at org.testng.Assert.assertEquals(Assert.java:178)
	at org.testng.Assert.assertEquals(Assert.java:188)
	at com.stta.ExampleCases.Assertion.Assert_Method_2(Assertion.java:40)
	at sun.reflect.NativeMethodAccessorImpl.invoke0(Native Method)
	at sun.reflect.NativeMethodAccessorImpl.invoke(Unknown Source)
	at sun.reflect.DelegatingMethodAccessorImpl.invoke(Unknown Source)
	at java.lang.reflect.Method.invoke(Unknown Source)
	at org.testng.internal.MethodInvocationHelper.invokeMethod(MethodInvocationHelper.java:85)
	at org.testng.internal.Invoker.invokeMethod(Invoker.java:639)
	at org.testng.internal.Invoker.invokeTestMethod(Invoker.java:816)
	at org.testng.internal.Invoker.invokeTestMethods(Invoker.java:1124)
	at org.testng.internal.TestMethodWorker.invokeTestMethods(TestMethodWorker.java:125)
	at org.testng.internal.TestMethodWorker.run(TestMethodWorker.java:108)
	at org.testng.TestRunner.privateRun(TestRunner.java:774)
	at org.testng.TestRunner.run(TestRunner.java:624)
	at org.testng.SuiteRunner.runTest(SuiteRunner.java:359)
	at org.testng.SuiteRunner.runSequentially(SuiteRunner.java:354)
	at org.testng.SuiteRunner.privateRun(SuiteRunner.java:312)
	at org.testng.SuiteRunner.run(SuiteRunner.java:261)
	at org.testng.SuiteRunnerWorker.runSuite(SuiteRunnerWorker.java:52)
	at org.testng.SuiteRunnerWorker.run(SuiteRunnerWorker.java:86)
	at org.testng.TestNG.runSuitesSequentially(TestNG.java:1215)
	at org.testng.TestNG.runSuitesLocally(TestNG.java:1140)
	at org.testng.TestNG.run(TestNG.java:1048)
	at org.testng.remote.AbstractRemoteTestNG.run(AbstractRemoteTestNG.java:126)
	at org.testng.remote.RemoteTestNG.initAndRun(RemoteTestNG.java:137)
	at org.testng.remote.RemoteTestNG.main(RemoteTestNG.java:58)
]]>
            </full-stacktrace>
          </exception> <!-- java.lang.AssertionError -->
          <reporter-output>
          </reporter-output>
        </test-method> <!-- Assert_Method_2 -->
        <test-method status="FAIL" signature="Assert_Method_3()[pri:0, instance:com.stta.ExampleCases.Assertion@cf93bb]" name="Assert_Method_3" duration-ms="614" started-at="2016-05-13T15:37:41Z" finished-at="2016-05-13T15:37:41Z">
          <exception class="java.lang.AssertionError">
            <message>
              <![CDATA[Expected and Actual are match]]>
            </message>
            <full-stacktrace>
              <![CDATA[java.lang.AssertionError: Expected and Actual are match
	at org.testng.Assert.fail(Assert.java:94)
	at org.testng.Assert.assertNotEquals(Assert.java:856)
	at com.stta.ExampleCases.Assertion.Assert_Method_3(Assertion.java:50)
	at sun.reflect.NativeMethodAccessorImpl.invoke0(Native Method)
	at sun.reflect.NativeMethodAccessorImpl.invoke(Unknown Source)
	at sun.reflect.DelegatingMethodAccessorImpl.invoke(Unknown Source)
	at java.lang.reflect.Method.invoke(Unknown Source)
	at org.testng.internal.MethodInvocationHelper.invokeMethod(MethodInvocationHelper.java:85)
	at org.testng.internal.Invoker.invokeMethod(Invoker.java:639)
	at org.testng.internal.Invoker.invokeTestMethod(Invoker.java:816)
	at org.testng.internal.Invoker.invokeTestMethods(Invoker.java:1124)
	at org.testng.internal.TestMethodWorker.invokeTestMethods(TestMethodWorker.java:125)
	at org.testng.internal.TestMethodWorker.run(TestMethodWorker.java:108)
	at org.testng.TestRunner.privateRun(TestRunner.java:774)
	at org.testng.TestRunner.run(TestRunner.java:624)
	at org.testng.SuiteRunner.runTest(SuiteRunner.java:359)
	at org.testng.SuiteRunner.runSequentially(SuiteRunner.java:354)
	at org.testng.SuiteRunner.privateRun(SuiteRunner.java:312)
	at org.testng.SuiteRunner.run(SuiteRunner.java:261)
	at org.testng.SuiteRunnerWorker.runSuite(SuiteRunnerWorker.java:52)
	at org.testng.SuiteRunnerWorker.run(SuiteRunnerWorker.java:86)
	at org.testng.TestNG.runSuitesSequentially(TestNG.java:1215)
	at org.testng.TestNG.runSuitesLocally(TestNG.java:1140)
	at org.testng.TestNG.run(TestNG.java:1048)
	at org.testng.remote.AbstractRemoteTestNG.run(AbstractRemoteTestNG.java:126)
	at org.testng.remote.RemoteTestNG.initAndRun(RemoteTestNG.java:137)
	at org.testng.remote.RemoteTestNG.main(RemoteTestNG.java:58)
]]>
            </full-stacktrace>
          </exception> <!-- java.lang.AssertionError -->
          <reporter-output>
          </reporter-output>
        </test-method> <!-- Assert_Method_3 -->
        <test-method status="PASS" signature="Assert_Method_4()[pri:0, instance:com.stta.ExampleCases.Assertion@cf93bb]" name="Assert_Method_4" duration-ms="368" started-at="2016-05-13T15:37:41Z" finished-at="2016-05-13T15:37:42Z">
          <reporter-output>
          </reporter-output>
        </test-method> <!-- Assert_Method_4 -->
        <test-method status="PASS" signature="Assert_Method_5()[pri:0, instance:com.stta.ExampleCases.Assertion@cf93bb]" name="Assert_Method_5" duration-ms="124" started-at="2016-05-13T15:37:42Z" finished-at="2016-05-13T15:37:42Z">
          <reporter-output>
          </reporter-output>
        </test-method> <!-- Assert_Method_5 -->
        <test-method status="FAIL" signature="Assert_Method_6()[pri:0, instance:com.stta.ExampleCases.Assertion@cf93bb]" name="Assert_Method_6" duration-ms="132" started-at="2016-05-13T15:37:42Z" finished-at="2016-05-13T15:37:42Z">
          <exception class="java.lang.AssertionError">
            <message>
              <![CDATA[Car checkbox is not selected expected [true] but found [false]]]>
            </message>
            <full-stacktrace>
              <![CDATA[java.lang.AssertionError: Car checkbox is not selected expected [true] but found [false]
	at org.testng.Assert.fail(Assert.java:94)
	at org.testng.Assert.failNotEquals(Assert.java:496)
	at org.testng.Assert.assertTrue(Assert.java:42)
	at com.stta.ExampleCases.Assertion.Assert_Method_6(Assertion.java:81)
	at sun.reflect.NativeMethodAccessorImpl.invoke0(Native Method)
	at sun.reflect.NativeMethodAccessorImpl.invoke(Unknown Source)
	at sun.reflect.DelegatingMethodAccessorImpl.invoke(Unknown Source)
	at java.lang.reflect.Method.invoke(Unknown Source)
	at org.testng.internal.MethodInvocationHelper.invokeMethod(MethodInvocationHelper.java:85)
	at org.testng.internal.Invoker.invokeMethod(Invoker.java:639)
	at org.testng.internal.Invoker.invokeTestMethod(Invoker.java:816)
	at org.testng.internal.Invoker.invokeTestMethods(Invoker.java:1124)
	at org.testng.internal.TestMethodWorker.invokeTestMethods(TestMethodWorker.java:125)
	at org.testng.internal.TestMethodWorker.run(TestMethodWorker.java:108)
	at org.testng.TestRunner.privateRun(TestRunner.java:774)
	at org.testng.TestRunner.run(TestRunner.java:624)
	at org.testng.SuiteRunner.runTest(SuiteRunner.java:359)
	at org.testng.SuiteRunner.runSequentially(SuiteRunner.java:354)
	at org.testng.SuiteRunner.privateRun(SuiteRunner.java:312)
	at org.testng.SuiteRunner.run(SuiteRunner.java:261)
	at org.testng.SuiteRunnerWorker.runSuite(SuiteRunnerWorker.java:52)
	at org.testng.SuiteRunnerWorker.run(SuiteRunnerWorker.java:86)
	at org.testng.TestNG.runSuitesSequentially(TestNG.java:1215)
	at org.testng.TestNG.runSuitesLocally(TestNG.java:1140)
	at org.testng.TestNG.run(TestNG.java:1048)
	at org.testng.remote.AbstractRemoteTestNG.run(AbstractRemoteTestNG.java:126)
	at org.testng.remote.RemoteTestNG.initAndRun(RemoteTestNG.java:137)
	at org.testng.remote.RemoteTestNG.main(RemoteTestNG.java:58)
]]>
            </full-stacktrace>
          </exception> <!-- java.lang.AssertionError -->
          <reporter-output>
          </reporter-output>
        </test-method> <!-- Assert_Method_6 -->
        <test-method status="PASS" signature="exitBrowser()[pri:0, instance:com.stta.ExampleCases.Assertion@cf93bb]" name="exitBrowser" is-config="true" duration-ms="115" started-at="2016-05-13T15:37:42Z" finished-at="2016-05-13T15:37:42Z">
          <reporter-output>
          </reporter-output>
        </test-method> <!-- exitBrowser -->
      </class> <!-- com.stta.ExampleCases.Assertion -->
    </test> <!-- Default test -->
  </suite> <!-- Default suite -->
</testng-results>
